Workbook

Sheet HDFC
A1: 88Academics
A2: Draft Pay Register for the month of September 2025
A4: PAY_DATE | B4: Employee Code | C4: Employee Name | D4: Date of Join | E4: Gender | F4: Date of Birth | G4: Date of Leaving | H4: Father Name | I4: Department | J4: Designation | K4: Cost_Centre | L4: Work Location | M4: UAN_No | N4: PAN | O4: Aadhaar Number | P4: Bank Name | Q4: Account_No | R4: IFSC_Code | S4: Name As Per Bank | T4: Nationality | U4: Mobile Number | V4: Email ID | W4: STDDAYS | X4: LOP DAYS | Y4: WRKDAYS | Z4: Basic | AA4: Basic Arrear | AB4: House Rent Allowance | AC4: HRA Arrear | AD4: Special Allowance | AE4: LOP Reversals | AF4: Total Salary | AG4: Salary Payable | AH4: TDS | AI4: Monthly TDS | AJ4: Provident Fund | AK4: PF Arrears | AL4: LWF | AM4: Net Salary Payable
AH5: 0
A6: 45930 | B6: 88A1004 | C6: Ajay Kumar Saxena | D6: 01/11/2021 | E6: M | F6: 20/06/1992 | H6: Late Jayant Kumar Lala | I6: Operations | J6: Manager | K6: NEW DELHI | L6: NEW DELHI | N6: DYDPS8248Q | O6: 336743542508 | P6: HDFC BANK LTD | Q6: 50100446028500 | R6: HDFC0004754 | S6: Ajay Kumar Saxena | T6: INDIAN | U6: 8527697925 | V6: aj.saxena0326@gmail.com | W6: 30 | X6: 0.6 | Y6: =W6-X6 -> 29.4 | Z6: 33275 | AA6: 0 | AB6: 16638 | AC6: 0 | AD6: 16638 | AF6: =SUM(Z6:AD6) -> 66551 | AG6: =ROUND(AF6/W6*Y6,0) -> 65220 | AJ6: 0 | AK6: 0 | AL6: 0 | AM6: =AG6-SUM(AI6:AL6) -> 65220 | AN6: 66551
A7: 45930 | B7: 88G1004 | C7: Simran Kumari Arora | D7: 01/11/2021 | E7: F | F7: 19/12/1996 | G7: 45930 | H7: Ramesh Arora | I7: Academic | J7: Asst. Manager | K7: NEW DELHI | L7: NEW DELHI | N7: DCXPA5508M | O7: 400878015992 | P7: HDFC BANK LTD | Q7: 50100367679688 | R7: HDFC0004754 | S7: Simran Arora | T7: INDIAN | U7: 7838783381 | V7: simranarora121996@gmail.com | W7: 30 | X7: 0 | Y7: =W7-X7 -> 30 | Z7: 0 | AA7: 0 | AB7: 0 | AC7: 0 | AD7: 0 | AF7: =SUM(Z7:AD7) -> 0 | AG7: =ROUND(AF7/W7*Y7,0) -> 0 | AJ7: 0 | AK7: 0 | AL7: 0 | AM7: =AG7-SUM(AI7:AL7) -> 0 | AP7: 23650
A8: 45930 | B8: 88G1013 | C8: Jyoti Pal | D8: 01/11/2021 | E8: F | F8: 22/05/1993 | H8: J.L Pal | I8: Marketing & Support | J8: Business Development Manager | K8: NEW DELHI | L8: NEW DELHI | N8: BRRPP8283K | O8: 863713103811 | P8: HDFC BANK LTD | Q8: 50100151532802 | R8: HDFC0000294 | S8: Jyoti Pal | T8: INDIAN | U8: 7982950540 | V8: sen.jyoti5@gmail.com | W8: 30 | X8: 0 | Y8: =W8-X8 -> 30 | Z8: 22000 | AA8: 0 | AB8: 11000 | AC8: 0 | AD8: 11000 | AF8: =SUM(Z8:AD8) -> 44000 | AG8: =ROUND(AF8/W8*Y8,0) -> 44000 | AJ8: 0 | AK8: 0 | AL8: 0 | AM8: =AG8-SUM(AI8:AL8) -> 44000 | AN8: 39600 | AO8: Increment
A9: 45930 | B9: 88G1032 | C9: Kiran Pathak | D9: 06/04/2022 | E9: F | F9: 09/07/1996 | G9: 45930 | H9: Mr. Shiv Charan Pathak | I9: Academic | J9: Asst. Manager | K9: NEW DELHI | L9: NEW DELHI | N9: DHPPP5580M | O9: 441344227722 | P9: HDFC BANK LTD | Q9: 50100570445568 | R9: HDFC0004754 | S9: Kiran Pathak | T9: INDIAN | U9: 9911369360 | V9: pathakkiran233@gmail.com | W9: 30 | X9: 0 | Y9: =W9-X9 -> 30 | Z9: 0 | AA9: 0 | AB9: 0 | AC9: 0 | AD9: 0 | AF9: =SUM(Z9:AD9) -> 0 | AG9: =ROUND(AF9/W9*Y9,0) -> 0 | AJ9: 0 | AK9: 0 | AL9: 0 | AM9: =AG9-SUM(AI9:AL9) -> 0 | AP9: 23650
A10: 45930 | B10: 88G1074 | C10: Rakesh Singh Rawat | D10: 14/03/2023 | E10: M | F10: 03/05/1976 | H10: Balwant Singh Rawat | I10: Academic | J10: Asst. Manager | K10: NEW DELHI | L10: NEW DELHI | N10: BUYPR5567C | O10: 621229408319 | P10: HDFC BANK LTD | Q10: 50100605279393 | R10: HDFC0003687 | S10: Rakesh Singh Rawat | T10: INDIAN | U10: 9013600858 | V10: rsrawatdtp9@gmail.com | W10: 30 | X10: 0 | Y10: =W10-X10 -> 30 | Z10: 21000 | AA10: 0 | AB10: 3200 | AC10: 0 | AD10: 0 | AF10: =SUM(Z10:AD10) -> 24200 | AG10: =ROUND(AF10/W10*Y10,0) -> 24200 | AJ10: 0 | AK10: 0 | AL10: 0 | AM10: =AG10-SUM(AI10:AL10) -> 24200 | AN10: 24200
A11: 45930 | B11: 88G1078 | C11: Pinku Kumar | D11: 10/05/2023 | E11: M | F11: 15/08/1996 | H11: Amresh Kumar Mishra | I11: VGLD | J11: SEO Executive | K11: NEW DELHI | L11: NEW DELHI | N11: CVZPK7257B | O11: 388227818863 | P11: HDFC BANK LTD | Q11: 50100754820324 | R11: HDFC0004754 | S11: Pinku Kumar | T11: INDIAN | U11: 9485963031 | V11: pinkudigitalmarketing@gmail.com | W11: 30 | X11: 0 | Y11: =W11-X11 -> 30 | Z11: 24100 | AA11: 0 | AB11: 12050 | AC11: 0 | AD11: 12050 | AF11: =SUM(Z11:AD11) -> 48200 | AG11: =ROUND(AF11/W11*Y11,0) -> 48200 | AJ11: 1800 | AK11: 0 | AL11: 0 | AM11: =AG11-SUM(AI11:AL11) -> 46400 | AN11: 46400
AH12: 0
B13: =COUNTA(B5:B11) -> 6 | G13: =COUNTA(G5:G11) -> 2 | T13: TOTAL | Z13: =SUM(Z5:Z12) -> 100375 | AA13: =SUM(AA5:AA12) -> 0 | AB13: =SUM(AB5:AB12) -> 42888 | AC13: =SUM(AC5:AC12) -> 0 | AD13: =SUM(AD5:AD12) -> 39688 | AF13: =SUM(AF5:AF12) -> 182951 | AG13: =SUM(AG5:AG12) -> 181620 | AI13: =SUM(AI5:AI12) -> 0 | AJ13: =SUM(AJ5:AJ12) -> 1800 | AK13: =SUM(AK5:AK12) -> 0 | AL13: =SUM(AL5:AL12) -> 0 | AM13: =SUM(AM5:AM12) -> 179820
Z15: 21000 | AA15: 0 | AB15: 5000 | AC15: 0 | AD15: 0 | AF15: =SUM(Z15:AD15) -> 26000
Z16: 22400 | AB16: 7600 | AF16: =SUM(Z16:AD16) -> 30000
Z17: =Z15-Z16 -> -1400 | AB17: =AB15-AB16 -> -2600

Sheet Draft-Paysheet May 2026
A1: 88Academics
A2: Draft Pay Register for the month of May 2026
P3: =AL3 -> 2693023.4 | Q3: 874538 | R3: =P3-Q3 -> 1818485.4 | AE3: =SUM(AE5:AE57) -> 2814163 | AL3: =SUBTOTAL(9,AL5:AL58) -> 2693023.4
A4: PAY_DATE | B4: Employee Code | C4: Employee Name | D4: Date of Join | E4: Gender | F4: Date of Birth | G4: Date of Leaving | H4: Father Name | I4: Department | J4: Designation | K4: Cost_Centre | L4: Work Location | M4: UAN_No | N4: PAN | O4: Aadhaar Number | P4: Bank Name | Q4: Account_No | R4: IFSC_Code | S4: Name As Per Bank | T4: Nationality | U4: Mobile Number | V4: Email ID | W4: STDDAYS | X4: LOP DAYS | Y4: WRKDAYS | Z4: Basic | AA4: Basic Arrear | AB4: House Rent Allowance | AC4: HRA Arrear | AD4: Special Allowance | AE4: Total Salary | AF4: Salary Payable | AG4: Other Banefit | AH4: Monthly TDS | AI4: Provident Fund | AJ4: Salary Deduction | AK4: LWF | AL4: Net Salary Payable
A5: 31-05-2026 | B5: 88A1001 | C5: Narayan Kasat | D5: 01/11/2021 | E5: M | F5: 27/06/1975 | H5: Mr. H.L.Kasat | I5: Management | J5: C.O.O | K5: NEW DELHI | L5: NEW DELHI | N5: AGAPK2560P | O5: 678252973676 | P5: AXIS BANK | Q5: 921010013386877 | R5: UTIB0004626 | S5: Narayan Kasat | T5: INDIAN | U5: 9891054411 | V5: narayan@88tuition.com | W5: 31 | Y5: =W5-X5 -> 31 | Z5: 150000 | AA5: 0 | AB5: 75000 | AC5: 0 | AD5: 75000 | AE5: =SUM(Z5:AD5) -> 300000 | AF5: =ROUND(AE5/W5*Y5,0) -> 300000 | AH5: =TDS!D25 -> 56907.5 | AI5: 0 | AJ5: 0 | AK5: 0 | AL5: =AF5-SUM(AH5:AK5) -> 243092.5
A6: 31-05-2026 | B6: 88A1002 | C6: Babu Lal | D6: 01/11/2021 | E6: M | F6: 07/02/1987 | H6: Bhagwan Sahay | I6: IT | J6: Project Head | K6: NEW DELHI | L6: NEW DELHI | N6: ADAPL0527A | O6: 725320397392 | P6: AXIS BANK | Q6: 911010047193187 | R6: UTIB0001007 | S6: Babu Lal | T6: INDIAN | U6: 9873030060 | V6: babulal0060@gmail.com | W6: 31 | Y6: =W6-X6 -> 31 | Z6: 99621 | AA6: 0 | AB6: 49810 | AC6: 0 | AD6: 49810 | AE6: =SUM(Z6:AD6) -> 199241 | AF6: =ROUND(AE6/W6*Y6,0) -> 199241 | AH6: =TDS!E25+2 -> 21989.753 | AI6: 0 | AJ6: 0 | AK6: 0 | AL6: =AF6-SUM(AH6:AK6) -> 177251.25
A7: 31-05-2026 | B7: 88A1003 | C7: Gulshan | D7: 01/11/2021 | E7: M | F7: 01/05/1999 | H7: J.P. Sharma | I7: Operations | J7: Manager | K7: NEW DELHI | L7: NEW DELHI | N7: CERPG0826H | O7: 830140509131 | P7: KARUR VYSYA BANK | Q7: 4101155000110629 | R7: KVBL0004101 | S7: Gulshan | T7: INDIAN | U7: 9717013679 | V7: gulshan12207@gmail.com | W7: 31 | Y7: =W7-X7 -> 31 | Z7: 47442 | AA7: 0 | AB7: 23721 | AC7: 0 | AD7: 23721 | AE7: =SUM(Z7:AD7) -> 94884 | AF7: =ROUND(AE7/W7*Y7,0) -> 94884 | AI7: 0 | AJ7: 0 | AK7: 0 | AL7: =AF7-SUM(AH7:AK7) -> 94884
A8: 31-05-2026 | B8: 88A1004 | C8: Ajay Kumar Saxena | D8: 01/11/2021 | E8: M | F8: 20/06/1992 | H8: Late Jayant Kumar Lala | I8: Operations | J8: Manager | K8: NEW DELHI | L8: NEW DELHI | N8: DYDPS8248Q | O8: 336743542508 | P8: HDFC BANK LTD | Q8: 50100446028500 | R8: HDFC0004754 | S8: Ajay Kumar Saxena | T8: INDIAN | U8: 8527697925 | V8: aj.saxena0326@gmail.com | W8: 31 | Y8: =W8-X8 -> 31 | Z8: =33275+3327-2 -> 36600 | AA8: 0 | AB8: =16638+1663-1 -> 18300 | AC8: 0 | AD8: =16638+1663-1 -> 18300 | AE8: =SUM(Z8:AD8) -> 73200 | AF8: =ROUND(AE8/W8*Y8,0) -> 73200 | AI8: 0 | AJ8: 0 | AK8: 0 | AL8: =AF8-SUM(AH8:AK8) -> 73200 | AN8: =AL8-AE8 -> 0
A9: 31-05-2026 | B9: 88G1001 | C9: Rashi Gupta | D9: 01/11/2021 | E9: F | F9: 19/03/1991 | H9: A. N. Gupta | I9: Academic | J9: Manager | K9: NEW DELHI | L9: NEW DELHI | N9: BDCPG4329J | O9: 366855676793 | P9: STATE BANK OF INDIA | Q9: 65122570810 | R9: SBIN0050324 | S9: Rashi Gupta | T9: INDIAN | U9: 9654365202 | V9: rashig350@gmail.com | W9: 31 | Y9: =W9-X9 -> 31 | Z9: 25000 | AA9: 0 | AB9: 6200 | AC9: 0 | AD9: 6200 | AE9: =SUM(Z9:AD9) -> 37400 | AF9: =ROUND(AE9/W9*Y9,0) -> 37400 | AI9: 0 | AJ9: 0 | AK9: 0 | AL9: =AF9-SUM(AH9:AK9) -> 37400
A10: 31-05-2026 | B10: 88G1003 | C10: Raj Kamal Sharma | D10: 01/11/2021 | E10: M | F10: 10/02/1989 | H10: Om Vir Sharma | I10: Academic | J10: Asst. Manager | K10: NEW DELHI | L10: NEW DELHI | N10: DEOPS7788G | O10: 432153723120 | P10: STATE BANK OF INDIA | Q10: 31582334723 | R10: SBIN0018166 | S10: Raj Kamal Sharma | T10: INDIAN | U10: 9968722755 | V10: 007kamalrajsharma@gmail.com | W10: 31 | Y10: =W10-X10 -> 31 | Z10: =21000+1000 -> 22000 | AA10: 0 | AB10: 7650 | AD10: 6650 | AE10: =SUM(Z10:AD10) -> 36300 | AF10: =ROUND(AE10/W10*Y10,0) -> 36300 | AG10: 1210 | AI10: 0 | AJ10: 0 | AK10: 0 | AL10: =AF10-SUM(AH10:AK10)+AG10 -> 37510
A11: 31-05-2026 | B11: 88G1007 | C11: Roshan Sharma | D11: 01/11/2021 | E11: M | F11: 14/06/1997 | H11: Jai Prakash Sharma | I11: Academic | J11: Asst. Manager | K11: NEW DELHI | L11: NEW DELHI | N11: CNJPR5123H | O11: 938129698636 | P11: BANK OF MAHARASHTRA | Q11: 60285501118 | R11: MAHB0001744 | S11: Roshan Sharma | T11: INDIAN | U11: 9911811713 | V11: roshansharma110043@gmail.com | W11: 31 | Y11: =W11-X11 -> 31 | Z11: 22138 | AA11: 0 | AB11: 11069 | AC11: 0 | AD11: 11069 | AE11: =SUM(Z11:AD11) -> 44276 | AF11: =ROUND(AE11/W11*Y11,0) -> 44276 | AI11: 0 | AJ11: 0 | AK11: 0 | AL11: =AF11-SUM(AH11:AK11) -> 44276
A12: 31-05-2026 | B12: 88G1011 | C12: Meenakshi Gosai | D12: 01/11/2021 | E12: F | F12: 05/01/1993 | H12: Late Kundan Lal | I12: Marketing & Support | J12: Business Development Manager | K12: NEW DELHI | L12: NEW DELHI | N12: BUQPG9684K | O12: 354855342339 | P12: INDIAN OVERSEAS BANK | Q12: 076601000061190 | R12: IOBA0000766 | S12: Meenakshi Gosai | T12: INDIAN | U12: 7042668809 | V12: meenakshigosai15@gmail.com | W12: 31 | Y12: =W12-X12 -> 31 | Z12: 23500 | AA12: 0 | AB12: =10750-500 -> 10250 | AC12: 0 | AD12: =10750-1500 -> 9250 | AE12: =SUM(Z12:AD12) -> 43000 | AF12: =ROUND(AE12/W12*Y12,0) -> 43000 | AI12: 0 | AJ12: 0 | AK12: 0 | AL12: =AF12-SUM(AH12:AK12) -> 43000
A13: 31-05-2026 | B13: 88G1012 | C13: Deepa Chandnani | D13: 01/11/2021 | E13: F | F13: 10/02/1989 | H13: Ghanshyam Bharwani | I13: Marketing & Support | J13: Business Development Manager | K13: NEW DELHI | L13: NEW DELHI | N13: AVLPB5695G | O13: 563133225753 | P13: STATE BANK OF INDIA | Q13: 51116630705 | R13: SBIN0032160 | S13: Deepa Chandnani | T13: INDIAN | U13: 9873452523 | V13: deepabharwanis@gmail.com | W13: 31 | Y13: =W13-X13 -> 31 | Z13: 23500 | AA13: 0 | AB13: 10500 | AC13: 0 | AD13: =9500-1500 -> 8000 | AE13: =SUM(Z13:AD13) -> 42000 | AF13: =ROUND(AE13/W13*Y13,0) -> 42000 | AI13: 0 | AJ13: 0 | AK13: 0 | AL13: =AF13-SUM(AH13:AK13) -> 42000
A14: 31-05-2026 | B14: 88G1013 | C14: Jyoti Pal | D14: 01/11/2021 | E14: F | F14: 22/05/1993 | H14: J.L Pal | I14: Marketing & Support | J14: Business Development Manager | K14: NEW DELHI | L14: NEW DELHI | N14: BRRPP8283K | O14: 863713103811 | P14: HDFC BANK LTD | Q14: 50100151532802 | R14: HDFC0000294 | S14: Jyoti Pal | T14: INDIAN | U14: 7982950540 | V14: sen.jyoti5@gmail.com | W14: 31 | Y14: =W14-X14 -> 31 | Z14: 24000 | AA14: 0 | AB14: 11000 | AC14: 0 | AD14: 9000 | AE14: =SUM(Z14:AD14) -> 44000 | AF14: =ROUND(AE14/W14*Y14,0) -> 44000 | AI14: 0 | AJ14: 0 | AK14: 0 | AL14: =AF14-SUM(AH14:AK14) -> 44000
A15: 31-05-2026 | B15: 88G1014 | C15: Nidhi Gupta | D15: 01/11/2021 | E15: F | F15: 27/10/1975 | H15: J. P. Gupta | I15: Marketing & Support | J15: Business Development Manager | K15: NEW DELHI | L15: NEW DELHI | N15: AEEPG1703Q | O15: 840497171317 | P15: Canara Bank | Q15: 110037818923 | R15: CNRB0003160 | S15: Nidhi Gupta | T15: INDIAN | U15: 9958127672 | V15: nidhi.gupta.ng90@gmail.com | W15: 31 | X15: =LOP!R21 -> 1.5 | Y15: =W15-X15 -> 29.5 | Z15: =24000+2400 -> 26400 | AA15: 0 | AB15: =8292+829 -> 9121 | AD15: =5292+529 -> 5821 | AE15: =SUM(Z15:AD15) -> 41342 | AF15: =ROUND(AE15/W15*Y15,0) -> 39342 | AI15: 0 | AJ15: 0 | AK15: 0 | AL15: =AF15-SUM(AH15:AK15) -> 39342
A16: 31-05-2026 | B16: 88G1022 | C16: Shalini Sharma | D16: 03/02/2022 | E16: F | F16: 03/07/1990 | H16: BINNI SHARMA | I16: Academic | J16: Manager | K16: NEW DELHI | L16: NEW DELHI | N16: DFDPS2978C | O16: 390094950274 | P16: STATE BANK OF INDIA | Q16: 20088263301 | R16: SBIN0011550 | S16: Shalini Sharma | T16: Indian | U16: 9999868854 | V16: sharmashalini0307@gmail.com | W16: 31 | Y16: =W16-X16 -> 31 | Z16: 22000 | AA16: 0 | AB16: 4500 | AC16: 0 | AD16: 3500 | AE16: =SUM(Z16:AD16) -> 30000 | AF16: =ROUND(AE16/W16*Y16,0) -> 30000 | AI16: 0 | AJ16: 0 | AK16: 0 | AL16: =AF16-SUM(AH16:AK16) -> 30000
A17: 31-05-2026 | B17: 88G1041 | C17: Vikas Panwar | D17: 01/07/2022 | E17: M | F17: 15/08/1994 | H17: Dilip Keshri | I17: IT | J17: Asst. Manager | K17: NEW DELHI | L17: NEW DELHI | N17: DNMPP4480B | O17: 557891030486 | P17: KOTAK MAHINDRA BANK | Q17: 5246430031 | R17: KKBK0004596 | S17: Vikas Panwar | T17: INDIAN | U17: 8755629335 | V17: vikashpanwar888@gmail.com | W17: 31 | Y17: =W17-X17 -> 31 | Z17: =24000+2400 -> 26400 | AA17: 0 | AB17: =7600-3000+460+40 -> 5100 | AC17: 0 | AD17: 0 | AE17: =SUM(Z17:AD17) -> 31500 | AF17: =ROUND(AE17/W17*Y17,0) -> 31500 | AI17: 0 | AJ17: 0 | AK17: 0 | AL17: =AF17-SUM(AH17:AK17) -> 31500
A18: 31-05-2026 | B18: 88G1064 | C18: Maheen Ajmali | D18: 13/10/2022 | E18: F | F18: 04/08/1997 | H18: Mohd Arif Ajmali | I18: Marketing & Support | J18: Business Development Manager | K18: NEW DELHI | L18: NEW DELHI | N18: CXGPA1055G | O18: 299829943417 | P18: STATE BANK OF INDIA | Q18: 35853508559 | R18: SBIN0005918 | S18: Maheen Ajmali | T18: INDIAN | U18: 9873907268 | V18: maheenajmali974@gmail.com | W18: 31 | Y18: =W18-X18 -> 31 | Z18: 23000 | AA18: 0 | AB18: 5600 | AC18: 0 | AD18: 0 | AE18: =SUM(Z18:AD18) -> 28600 | AF18: =ROUND(AE18/W18*Y18,0) -> 28600 | AI18: 0 | AJ18: 0 | AK18: 0 | AL18: =AF18-SUM(AH18:AK18) -> 28600
A19: 31-05-2026 | B19: 88G1078 | C19: Pinku Kumar | D19: 10/05/2023 | E19: M | F19: 15/08/1996 | H19: Amresh Kumar Mishra | I19: VGLD | J19: SEO Executive | K19: NEW DELHI | L19: NEW DELHI | N19: CVZPK7257B | O19: 388227818863 | P19: HDFC BANK LTD | Q19: 50100754820324 | R19: HDFC0004754 | S19: Pinku Kumar | T19: INDIAN | U19: 9485963031 | V19: pinkudigitalmarketing@gmail.com | W19: 31 | Y19: =W19-X19 -> 31 | Z19: 28100 | AA19: 0 | AB19: 12050 | AC19: 0 | AD19: 8050 | AE19: =SUM(Z19:AD19) -> 48200 | AF19: =ROUND(AE19/W19*Y19,0) -> 48200 | AG19: 0 | AI19: 1800 | AJ19: 0 | AK19: 0 | AL19: =AF19-SUM(AH19:AK19)-AG19 -> 46400
A20: 31-05-2026 | B20: 88G1087 | C20: Arpit Acharya | D20: 30/10/2023 | E20: M | F20: 23/09/1997 | H20: Vimal Acharya | I20: VGLD | J20: Business Development Manager | K20: NEW DELHI | L20: NEW DELHI | N20: CQVPA0022P | O20: 928630894864 | P20: HDFC BANK LTD | Q20: 50100823730034 | R20: HDFC0007285 | S20: Arpit Acharya | T20: INDIAN | U20: 8268890388 | V20: arpitacharya23@gmail.com | W20: 31 | Y20: =W20-X20 -> 31 | Z20: 27912 | AA20: 0 | AB20: 13957 | AC20: 0 | AD20: 13957 | AE20: =SUM(Z20:AD20) -> 55826 | AF20: =ROUND(AE20/W20*Y20,0) -> 55826 | AI20: 1800 | AJ20: 0 | AK20: 0 | AL20: =AF20-SUM(AH20:AK20) -> 54026
A21: 31-05-2026 | B21: 88V1003 | C21: Rachna Ajmani | D21: 01/11/2021 | E21: F | F21: 02/10/1980 | H21: Lt. Sh. Harish Chander Batra | I21: VGLD | J21: Business Development Manager | K21: NEW DELHI | L21: NEW DELHI | N21: BHIPA7769N | O21: 215770644706 | P21: HDFC BANK LTD | Q21: 50100067622091 | R21: HDFC0001657 | S21: Rachna Ajmani | T21: INDIAN | U21: 8527697922 | V21: rachna@vglearningdestination.com | W21: 31 | X21: =LOP!R27 -> 1 | Y21: =W21-X21 -> 30 | Z21: =24000+2400 -> 26400 | AA21: 0 | AB21: =6000+600 -> 6600 | AC21: 0 | AD21: =3000+300 -> 3300 | AE21: =SUM(Z21:AD21) -> 36300 | AF21: =ROUND(AE21/W21*Y21,0) -> 35129 | AI21: 0 | AJ21: 0 | AK21: 0 | AL21: =AF21-SUM(AH21:AK21) -> 35129
A22: 31-05-2026 | B22: 88V1012 | C22: Sandeep Maurya | D22: 02/01/2022 | E22: M | F22: 25/08/1997 | H22: Jayprakash Maurya | I22: IT | J22: Mobile Application Developer | K22: NEW DELHI | L22: NEW DELHI | N22: DEFPM3399Q | O22: 233161412775 | P22: ICICI Bank | Q22: 051601003530 | R22: ICIC0000815 | S22: Sandeep Maurya | T22: INDIAN | U22: 7379258598 | V22: me.sandy00@gmail.com | W22: 31 | Y22: =W22-X22 -> 31 | Z22: 41182 | AA22: 0 | AB22: 20591 | AC22: 0 | AD22: 20591 | AE22: =SUM(Z22:AD22) -> 82364 | AF22: =ROUND(AE22/W22*Y22,0) -> 82364 | AI22: 0 | AJ22: 0 | AK22: 0 | AL22: =AF22-SUM(AH22:AK22) -> 82364
A23: 31-05-2026 | B23: 88V1018 | C23: Priya Madan | D23: 01/08/2022 | E23: F | F23: 03/03/1985 | H23: SUBHASH BANGERA | I23: VGLD | J23: Business Development Manager | K23: NEW DELHI | L23: NEW DELHI | N23: APQPB6598D | O23: 941384090856 | P23: AXIS BANK | Q23: 911010066143864 | R23: UTIB0000739 | S23: Priya Madan | T23: INDIAN | U23: 9654797629 | V23: priya.madan331985@gmail.com | W23: 31 | X23: 2 | Y23: =W23-X23 -> 29 | Z23: =22026+2203 -> 24229 | AA23: 0 | AB23: =7637+764 -> 8401 | AD23: =6637+663 -> 7300 | AE23: =SUM(Z23:AD23) -> 39930 | AF23: =ROUND(AE23/W23*Y23,0) -> 37354 | AH23: 0 | AI23: 0 | AJ23: 515 | AK23: 0 | AL23: =AF23-SUM(AH23:AK23)+AG23 -> 36839
A24: 31-05-2026 | B24: 88V1024 | C24: Monika Dhingra | D24: 19/12/2022 | E24: F | F24: 11/11/1982 | I24: VGLD | J24: Evaluation Support Executive | K24: NEW DELHI | L24: NEW DELHI | N24: AGKPD1159K | O24: 936304152231 | P24: ICICI Bank | Q24: 630101511988 | R24: ICIC0006301 | S24: Monika Dhingra | T24: INDIAN | U24: 9873040788 | V24: monikadh11@gmail.com | W24: 31 | Y24: =W24-X24 -> 31 | Z24: 23100 | AA24: 0 | AB24: 8250 | AC24: 0 | AD24: 8250 | AE24: =SUM(Z24:AD24) -> 39600 | AF24: =ROUND(AE24/W24*Y24,0) -> 39600 | AI24: 0 | AJ24: 0 | AK24: 0 | AL24: =AF24-SUM(AH24:AK24) -> 39600
A25: 31-05-2026 | B25: 88V1029 | C25: Sandeep | D25: 01/04/2023 | E25: M | F25: 28/11/1987 | H25: Shri Sudama Prasad Gupta | I25: VGLD | J25: Operations Executive | K25: NEW DELHI | L25: NEW DELHI | N25: BTAPS8845P | O25: 683236866217 | P25: HDFC BANK LTD | Q25: 50100255004836 | R25: HDFC0000026 | S25: Sandeep | T25: INDIAN | U25: 9582781076 | V25: sandeepguptaseo@gmail.com | W25: 31 | Y25: =W25-X25 -> 31 | Z25: 23100 | AA25: 0 | AB25: 7480 | AC25: 0 | AD25: 0 | AE25: =SUM(Z25:AD25) -> 30580 | AF25: =ROUND(AE25/W25*Y25,0) -> 30580 | AI25: 0 | AJ25: 0 | AK25: 0 | AL25: =AF25-SUM(AH25:AK25) -> 30580
A26: 31-05-2026 | B26: 88V1032 | C26: Mohd Ubaid | D26: 01/04/2023 | E26: M | F26: 15/06/1997 | H26: Mohd Haseen | I26: VGLD | J26: Business Development Manager | K26: NEW DELHI | L26: NEW DELHI | N26: AHEPU6987F | O26: 950525699650 | P26: HDFC BANK LTD | Q26: 50100262389811 | R26: HDFC0000708 | S26: Mohd Ubaid | T26: INDIAN | U26: 9999314704 | V26: ubaidkhan6166@gmail.com | W26: 31 | Y26: =W26-X26 -> 31 | Z26: 38800 | AA26: 0 | AB26: 18900 | AC26: 0 | AD26: 18900 | AE26: =SUM(Z26:AD26) -> 76600 | AF26: =ROUND(AE26/W26*Y26,0) -> 76600 | AI26: 1800 | AJ26: 0 | AK26: 0 | AL26: =AF26-SUM(AH26:AK26) -> 74800
A27: 31-05-2026 | B27: 88V1033 | C27: Jyoti Singh | D27: 01/04/2023 | E27: F | F27: 05/10/1997 | H27: Late Mr Madan pal Singh | I27: VGLD | J27: Operations Executive | K27: NEW DELHI | L27: NEW DELHI | N27: LXKPS2332B | O27: 335290214255 | P27: ICICI Bank | Q27: 721801500772 | R27: ICIC0007218 | S27: Jyoti Singh | T27: INDIAN | U27: 7982537821 | V27: jyotisingh23839@gmail.com | W27: 31 | Y27: =W27-X27 -> 31 | Z27: 23100 | AA27: 0 | AB27: 7150 | AC27: 0 | AD27: 0 | AE27: =SUM(Z27:AD27) -> 30250 | AF27: =ROUND(AE27/W27*Y27,0) -> 30250 | AI27: 0 | AJ27: 0 | AK27: 0 | AL27: =AF27-SUM(AH27:AK27) -> 30250
A28: 31-05-2026 | B28: 88V1035 | C28: Sugandha Bhatnagar | D28: 01/04/2023 | E28: F | F28: 22/05/1988 | H28: Vivek bhatnagar | I28: VGLD | J28: Business Development Manager | K28: NEW DELHI | L28: NEW DELHI | N28: BJYPB9879A | O28: 756329670090 | P28: Indian Bank | Q28: 59084158508 | R28: IDIB000T553 | S28: Sugandha | T28: INDIAN | U28: 8534999427 | V28: sugandhabhatnagar0121@gmail.com | W28: 31 | Y28: =W28-X28 -> 31 | Z28: 23100 | AA28: 0 | AB28: 7700 | AC28: 0 | AD28: 7700 | AE28: =SUM(Z28:AD28) -> 38500 | AF28: =ROUND(AE28/W28*Y28,0) -> 38500 | AI28: 0 | AJ28: 0 | AK28: 0 | AL28: =AF28-SUM(AH28:AK28) -> 38500
A29: 31-05-2026 | B29: 88V1047 | C29: Porikhit Das | D29: 14/08/2023 | E29: M | F29: 10/10/1994 | H29: Raju Das | I29: VGLD | J29: Business Development Manager | K29: NEW DELHI | L29: NEW DELHI | N29: BXHPD3077M | O29: 361057786305 | P29: KOTAK MAHINDRA BANK | Q29: 7546347903 | R29: KKBK0004575 | S29: Porikhit Das | T29: INDIAN | U29: 8135820955 | V29: porikhitdas16@gmail.com | W29: 31 | X29: =LOP!R36 -> 2 | Y29: =W29-X29 -> 29 | Z29: 30250 | AA29: 0 | AB29: 15125 | AC29: 0 | AD29: 15125 | AE29: =SUM(Z29:AD29) -> 60500 | AF29: =ROUND(AE29/W29*Y29,0) -> 56597 | AI29: 0 | AJ29: 0 | AK29: 0 | AL29: =AF29-SUM(AH29:AK29)-AG29 -> 56597
A30: 31-05-2026 | B30: 88V1050 | C30: Manazir | D30: 18/09/2023 | E30: M | F30: 10/09/2000 | H30: Afaq Ahmad | I30: VGLD | J30: Business Development Manager | K30: NEW DELHI | L30: NEW DELHI | N30: EYZPM8286B | O30: 629843778596 | P30: HDFC BANK LTD | Q30: 50100683165229 | R30: HDFC0004754 | S30: Manazir | T30: INDIAN | U30: 7678985427 | V30: mr.afaq12345@gmail.com | W30: 31 | Y30: =W30-X30 -> 31 | Z30: 24750 | AA30: 0 | AB30: 12375 | AC30: 0 | AD30: 12375 | AE30: =SUM(Z30:AD30) -> 49500 | AF30: =ROUND(AE30/W30*Y30,0) -> 49500 | AI30: 0 | AJ30: 0 | AK30: 0 | AL30: =AF30-SUM(AH30:AK30) -> 49500 | AN30: =AE30-AL30 -> 0
A31: 31-05-2026 | B31: 88V1051 | C31: Shohrab Haidar | D31: 01/09/2023 | E31: M | F31: 20/04/1998 | H31: Afzal hussain | I31: VGLD | J31: Business Development Manager | K31: NEW DELHI | L31: NEW DELHI | N31: ARPPH2377D | O31: 634825133916 | P31: PUNJAB AND SIND BANK | Q31: 14952122003500 | R31: PUNB0509610 | S31: Shohrab Haidar | T31: INDIAN | U31: 9773605547 | V31: sohrabhaider97@gmail.com | W31: 31 | Y31: =W31-X31 -> 31 | Z31: 26500 | AA31: 0 | AB31: 9000 | AC31: 0 | AD31: 6500 | AE31: =SUM(Z31:AD31) -> 42000 | AF31: =ROUND(AE31/W31*Y31,0) -> 42000 | AI31: 0 | AJ31: 0 | AK31: 0 | AL31: =AF31-SUM(AH31:AK31) -> 42000
A32: 31-05-2026 | B32: 88V1052 | C32: Anita Dubey | D32: 16/11/2023 | E32: F | F32: 12/08/1976 | H32: P DP CHOURASIA | I32: VGLD | J32: General Manager | K32: NEW DELHI | L32: NEW DELHI | N32: AMFPD7530B | O32: 765803347470 | P32: ICICI Bank | Q32: 631201503816 | R32: ICIC0006312 | S32: Anita Dubey | T32: INDIAN | U32: 9912990661 | V32: anitadubay@gmail.com | W32: 31 | Y32: =W32-X32 -> 31 | Z32: 54167 | AA32: 0 | AB32: 27083 | AC32: 0 | AD32: 27083 | AE32: =SUM(Z32:AD32) -> 108333 | AF32: =ROUND(AE32/W32*Y32,0) -> 108333 | AH32: =TDS!F52 -> 6315.3935 | AI32: 0 | AJ32: 0 | AK32: 0 | AL32: =AF32-SUM(AH32:AK32) -> 102017.61
A33: 31-05-2026 | B33: 88V1062 | C33: Parth Dilip Saraiya | D33: 22/01/2024 | E33: M | F33: 14/04/1995 | H33: Dilip Prabhudas Saraiya | I33: VGLD | J33: Sr. Executive | K33: NEW DELHI | L33: NEW DELHI | N33: FUNPS2736H | O33: 384092122476 | P33: HDFC BANK LTD | Q33: 50100461863868 | R33: HDFC0000489 | S33: Parth Dilip Saraiya | T33: INDIAN | U33: 7506327714 | V33: parthsaraiya77@gmail.com | W33: 31 | Y33: =W33-X33 -> 31 | Z33: 43920 | AA33: 0 | AB33: 19440 | AC33: 0 | AD33: 14640 | AE33: =SUM(Z33:AD33) -> 78000 | AF33: =ROUND(AE33/W33*Y33,0) -> 78000 | AI33: 0 | AJ33: 0 | AK33: 0 | AL33: =AF33-SUM(AH33:AK33) -> 78000
A34: 31-05-2026 | B34: 88V1067 | C34: Sangita Chaurasia | D34: 08/02/2024 | E34: F | F34: 30/03/1974 | H34: Sangeeta Chourasia | I34: VGLD | J34: Senior Business Development Manager | K34: NEW DELHI | L34: NEW DELHI | N34: AGFPC0825Q | O34: 415140302515 | P34: HDFC BANK LTD | Q34: 12281050015374 | R34: HDFC0001228 | S34: Sangeeta Chourasia | T34: INDIAN | U34: 7893566120 | V34: sangeetachourasia1977@gmail.com | W34: 31 | Y34: =W34-X34 -> 31 | Z34: 35457 | AA34: 0 | AB34: 16032 | AC34: 0 | AD34: 12511 | AE34: =SUM(Z34:AD34) -> 64000 | AF34: =ROUND(AE34/W34*Y34,0) -> 64000 | AI34: 0 | AJ34: 0 | AK34: 0 | AL34: =AF34-SUM(AH34:AK34)+AG34 -> 64000
A35: 31-05-2026 | B35: 88V1076 | C35: Alok Kumar Srivastava | D35: 01/04/2024 | E35: M | F35: 02/01/1977 | H35: Awdesh prasad | I35: VGLD | J35: Manager | K35: NEW DELHI | L35: NEW DELHI | N35: BSCPS3651L | O35: 881174158755 | P35: HDFC BANK LTD | Q35: 50100197657364 | R35: HDFC0004754 | S35: Alok Kumar Srivastava | T35: Indian | U35: 9268048522 | V35: aloksrivastva01@gmail.com | W35: 31 | Y35: =W35-X35 -> 31 | Z35: =25000+2500 -> 27500 | AA35: 0 | AB35: =11000+1100 -> 12100 | AC35: 0 | AD35: =8000+800 -> 8800 | AE35: =SUM(Z35:AD35) -> 48400 | AF35: =ROUND(AE35/W35*Y35,0) -> 48400 | AI35: 0 | AJ35: 0 | AK35: 0 | AL35: =AF35-SUM(AH35:AK35) -> 48400
A36: 31-05-2026 | B36: 88V1077 | C36: Aman Kumar | D36: 08/04/2024 | E36: M | F36: 03/02/2001 | H36: Ashok Kumar | I36: VGLD | J36: Business Development Manager | K36: NEW DELHI | L36: NEW DELHI | N36: JUSPK9115H | O36: 940911811731 | P36: HDFC BANK LTD | Q36: 50100832643671 | R36: HDFC0004754 | S36: Aman Kumar | T36: Indian | U36: 7678231846 | V36: amanammu0001@gmail.com | W36: 31 | Y36: =W36-X36 -> 31 | Z36: 23500 | AA36: 0 | AB36: 5500 | AC36: 0 | AD36: 0 | AE36: =SUM(Z36:AD36) -> 29000 | AF36: =ROUND(AE36/W36*Y36,0) -> 29000 | AI36: 0 | AJ36: 0 | AK36: 0 | AL36: =AF36-SUM(AH36:AK36) -> 29000
A37: 31-05-2026 | B37: 88V1085 | C37: Manmohan Singh Rawat | D37: 17/05/2024 | E37: M | F37: 20/07/1982 | H37: L S Rawat | I37: VGLD | J37: General Manager | K37: NEW DELHI | L37: NEW DELHI | N37: AKKPR9916L | O37: 988868176956 | P37: HDFC BANK LTD | Q37: 50100286871518 | R37: HDFC0002005 | S37: Manmohan Singh Rawat | T37: Indian | U37: 9643817909 | V37: rawatsinghmanmohan@gmail.com | W37: 31 | Y37: =W37-X37 -> 31 | Z37: 37400 | AA37: 0 | AB37: 18700 | AC37: 0 | AD37: 18700 | AE37: =SUM(Z37:AD37) -> 74800 | AF37: =ROUND(AE37/W37*Y37,0) -> 74800 | AI37: 0 | AJ37: 0 | AK37: 0 | AL37: =AF37-SUM(AH37:AK37) -> 74800
A38: 31-05-2026 | B38: 88V1089 | C38: Chetan Bisht | D38: 10/06/2024 | E38: M | F38: 07/07/1999 | H38: Narottam Bisht | I38: VGLD | J38: Senior Business Development Manager | K38: NEW DELHI | L38: NEW DELHI | N38: CZSPB6257M | O38: 781244878416 | P38: AXIS BANK | Q38: 922010024097820 | R38: UTIB0004122 | S38: Chetan Bisht | T38: Indian | U38: 9315688493 | V38: chetanbisht2715@gmail.com | W38: 31 | Y38: =W38-X38 -> 31 | Z38: 27500 | AA38: 0 | AB38: 13750 | AC38: 0 | AD38: 13750 | AE38: =SUM(Z38:AD38) -> 55000 | AF38: =ROUND(AE38/W38*Y38,0) -> 55000 | AI38: 0 | AJ38: 0 | AK38: 0 | AL38: =AF38-SUM(AH38:AK38) -> 55000
A39: 31-05-2026 | B39: 88V1090 | C39: Nitin Parashar | D39: 10/06/2024 | E39: M | F39: 01/04/1998 | H39: Manoj Parashar | I39: VGLD | J39: Business Development Manager | K39: NEW DELHI | L39: NEW DELHI | N39: DCTPP9267A | O39: 200341906859 | P39: HDFC BANK LTD | Q39: 50100744847754 | R39: HDFC0000279 | S39: Nitin Parashar | T39: Indian | U39: 9582026264 | V39: nitinparashar43@gmail.com | W39: 31 | Y39: =W39-X39 -> 31 | Z39: 23100 | AA39: 0 | AB39: 11550 | AC39: 0 | AD39: 11550 | AE39: =SUM(Z39:AD39) -> 46200 | AF39: =ROUND(AE39/W39*Y39,0) -> 46200 | AI39: 0 | AJ39: 0 | AK39: 0 | AL39: =AF39-SUM(AH39:AK39) -> 46200
A40: 31-05-2026 | B40: 88V1091 | C40: Sanjay Tewari | D40: 10/06/2024 | E40: M | F40: 01/07/1990 | H40: Lalit Prasad Tewari | I40: VGLD | J40: Business Development Executive | K40: NEW DELHI | L40: NEW DELHI | N40: AJKPT5665R | O40: 429920718466 | P40: HDFC BANK LTD | Q40: 50100485721253 | R40: HDFC0002061 | S40: Sanjay Tewari | T40: Indian | U40: 9999476208 | V40: sanjay01tewari@gmail.com | W40: 31 | X40: =LOP!R50 -> 0.5 | Y40: =W40-X40 -> 30.5 | Z40: 22000 | AA40: 0 | AB40: =4000-1000 -> 3000 | AC40: 0 | AD40: 0 | AE40: =SUM(Z40:AD40) -> 25000 | AF40: =ROUND(AE40/W40*Y40,0) -> 24597 | AI40: 0 | AJ40: 0 | AK40: 0 | AL40: =AF40-SUM(AH40:AK40) -> 24597
...

Sheet LOP
A1: May_2026 Attendance Summary - 01.05.2026 To 31.05.2026
A2: Sr. No. | B2: Assigned to | C2: Employee | D2: UID | E2: Employee Name | F2: Total Working days | G2: Half Day | H2: Absent | I2: Late upto 10:30 | J2: Late more than half an hour | K2: LOP for Late | L2: Holiday working | M2: Remarks | N2: CL | O2: SL | P2: PL | Q2: Optional Holiday | R2: LOP | S2: Punching Missing | T2: Work from home
A3: 1 | B3: Gulshan | C3: 88 | D3: 88A1003 | E3: Gulshan | F3: 31 | G3: - | H3: - | I3: - | J3: - | K3: -
A4: 2 | B4: Ajay Saxena | C4: 88 | D4: 88A1004 | E4: AJAY SAXENA | F4: 31 | G4: 0 | H4: 1 | I4: 0 | J4: 0 | K4: 0 | N4: 0 | O4: 1 | P4: 0 | Q4: 0 | R4: 0
A5: 3 | B5: Manazir | C5: VGLD | D5: 88E1114 | E5: Pooja | F5: 31 | G5: 0 | H5: 0 | I5: 0 | J5: 0 | K5: 0 | N5: 0 | O5: 0 | P5: 0 | Q5: 0 | R5: 0
A6: 4 | B6: PRIYA MADAN | C6: VGLD | D6: 88E1115 | E6: Divya Thakur | F6: 31 | G6: 0 | H6: 2 | I6: 0 | J6: 1 | K6: 0 | M6: Late upto 10:30= 07 | N6: 0 | O6: 0 | P6: 0 | Q6: 0 | R6: 2 | S6: 1
A7: 5 | B7: Ubaid | C7: VGLD | D7: 88E1116 | E7: Babita | F7: 31 | G7: 0 | H7: 15 | I7: 0 | J7: 0 | K7: 0 | N7: 0 | O7: 0 | P7: 1 | Q7: 1 | R7: 13
A8: 6 | B8: Arpit Acharya | C8: VGLD | D8: 88E1120 | E8: Kunal Kashyap | F8: 31 | G8: - | H8: - | I8: - | J8: - | K8: - | N8: 0 | O8: 0 | P8: 0 | Q8: 0 | R8: 0
A9: 7 | B9: Ajay Saxena | C9: VGLD | D9: 88E1121 | E9: Shivam | F9: 31 | G9: 0 | H9: 1 | I9: 2 | J9: 0 | K9: 0 | N9: 0 | O9: 0 | P9: 1 | Q9: 0 | R9: 0
A10: 8 | B10: Arpit Acharya | C10: VGLD | D10: 88E1122 | E10: Shahwaiz Ajmali | F10: 31 | G10: 2 | H10: 6 | I10: 0 | J10: 0 | K10: 0 | N10: 0.5 | O10: 0.5 | P10: 2 | Q10: 1 | R10: 3
A11: 9 | B11: Manazir | C11: VGLD | D11: 88E1124 | E11: Dev Karan | F11: 31 | G11: 4 | H11: 0 | I11: 2 | J11: 0 | K11: 0 | M11: Late upto 10:30= 19 | N11: 0 | O11: 0 | P11: 0 | Q11: 0 | R11: 2
A12: 10 | B12: PINKU KUMAR | C12: VGLD | D12: 88E1125 | E12: Sakshi | F12: 31 | G12: 0 | H12: 1 | I12: 0 | J12: 0 | K12: 0 | N12: 1 | O12: 0 | P12: 0 | Q12: 0 | R12: 0
A13: 11 | B13: Ajay Saxena | C13: VGLD | D13: 88E1126 | E13: Juhi Kumari | F13: 31 | G13: 2 | H13: 3 | I13: 0 | J13: 0 | K13: 0 | M13: Late upto 10:30= 06 | N13: 1 | O13: 1 | P13: 1 | Q13: 0 | R13: 1 | S13: 1
A14: 12 | B14: Arpit Acharya | C14: VGLD | D14: 88E1127 | E14: Abdul | F14: 31 | G14: 4 | H14: 3 | I14: 0 | J14: 0 | K14: 0 | M14: Late upto 10:30= 05 | N14: 0.5 | O14: 0 | P14: 1 | Q14: 1 | R14: 2.5 | S14: 1
A15: 13 | B15: Ajay Saxena | C15: VGLD | D15: 88E1129 | E15: Akash | F15: 31 | G15: 1 | H15: 0 | I15: 3 | J15: 0 | K15: 0 | N15: 0.5 | O15: 0 | P15: 0 | Q15: 0 | R15: 0
A16: 14 | B16: PINKU KUMAR | C16: VGLD | D16: 88E1132 | E16: Khushi Kumari | F16: 31 | G16: 0 | H16: 2 | I16: 0 | J16: 0 | K16: 0 | N16: 1 | O16: 1 | P16: 0 | Q16: 0 | R16: 0
A17: 15 | B17: Raj Kamal | C17: 88 | D17: 88G1001 | E17: Rashi Gupta | F17: 31 | G17: - | H17: - | I17: - | J17: - | K17: - | N17: 0 | O17: 0 | P17: 1 | Q17: 0 | R17: 0
A18: 16 | B18: Raj Kamal | C18: 88 | D18: 88G1003 | E18: RAJ | F18: 31 | G18: 1 | H18: 5 | I18: 0 | J18: 0 | K18: 0 | N18: 0.5 | O18: 0 | P18: 5 | Q18: 0 | R18: 0
A19: 17 | B19: Gulshan | C19: 88 | D19: 88G1011 | E19: Meenakshi Gosai | F19: 31 | G19: - | H19: - | I19: - | J19: - | K19: -
A20: 18 | B20: Gulshan | C20: 88 | D20: 88G1012 | E20: Deepa Chandnani | F20: 31 | G20: - | H20: - | I20: - | J20: - | K20: -
A21: 19 | B21: Ubaid | C21: 88 | D21: 88G1014 | E21: Nidhi | F21: 31 | G21: 1 | H21: 3 | I21: 0 | J21: 0 | K21: 0 | M21: Late upto 10:30= 22 | N21: 0.5 | O21: 0.5 | P21: 1 | Q21: 0 | R21: 1.5
A22: 20 | B22: Raj Kamal | C22: 88 | D22: 88G1022 | E22: SHALINI | F22: 31 | G22: - | H22: - | I22: - | J22: - | K22: -
A23: 21 | B23: Ajay Saxena | C23: 88 | D23: 88G1041 | E23: VIKAS PAWAR | F23: 31 | G23: 0 | H23: 1 | I23: 1 | J23: 0 | K23: 0 | N23: 0 | O23: 1 | P23: 0 | Q23: 0 | R23: 0
A24: 22 | B24: Gulshan | C24: 88 | D24: 88G1064 | E24: Maheen Ajmali | F24: 31 | G24: - | H24: - | I24: - | J24: - | K24: - | N24: 0 | O24: 0 | P24: 1 | Q24: 1 | R24: 0
A25: 23 | B25: PINKU KUMAR | C25: 88 | D25: 88G1078 | E25: PINKU KUMAR | F25: 31 | G25: 0 | H25: 0 | I25: 0 | J25: 0 | K25: 0 | N25: 0 | O25: 0 | P25: 0 | Q25: 0 | R25: 0
A26: 24 | B26: Arpit Acharya | C26: 88 | D26: 88G1087 | E26: ARPIT ACHARYA | F26: 31 | G26: - | H26: - | I26: - | J26: - | K26: - | N26: 1 | O26: 0 | P26: 0 | Q26: 0 | R26: 0
A27: 25 | B27: Self | C27: 88 | D27: 88V1003 | E27: RACHNA AJMANI | F27: 31 | G27: 2 | H27: 2 | I27: 3 | J27: 0 | K27: 0 | M27: Late upto 10:30= 19 | N27: 0.5 | O27: 0.5 | P27: 1 | Q27: 0 | R27: 1
A28: 26 | B28: Self | C28: 88 | D28: 88V1006 | E28: SHALU | F28: 31 | G28: - | H28: - | I28: - | J28: - | K28: -
A29: 27 | B29: Gulshan | C29: 88 | D29: 88V1012 | E29: Sandeep Maurya | F29: 31 | G29: - | H29: - | I29: - | J29: - | K29: -
A30: 28 | B30: PRIYA MADAN | C30: 88 | D30: 88V1018 | E30: PRIYA MADAN | F30: 31 | G30: 1 | H30: 5 | I30: 1 | J30: 0 | K30: 0 | M30: Late upto 10:30= 16 | N30: 0.5 | O30: 0 | P30: 1 | Q30: 0 | R30: 4 | S30: Consider 2 days as work from home then 20% salary will deduct
A31: 29 | B31: MONIKA | C31: 88 | D31: 88V1024 | E31: MONIKA | F31: 31 | G31: 2 | H31: 0 | I31: 0 | J31: 0 | K31: 0 | N31: 0.5 | O31: 0.5 | P31: 0 | Q31: 0 | R31: 0
A32: 30 | B32: Manazir | C32: 88 | D32: 88V1029 | E32: SANDEEP GUPTA | F32: 31 | G32: 1 | H32: 2 | I32: 1 | J32: 1 | K32: 0 | N32: 0.5 | O32: 0.5 | P32: 2 | Q32: 0 | R32: 0
A33: 31 | B33: Ubaid | C33: 88 | D33: 88V1032 | E33: UBAID | F33: 31 | G33: 0 | H33: 1 | I33: 0 | J33: 0 | K33: 0 | M33: Late upto 10:30= 21 | N33: 0 | O33: 0 | P33: 1 | Q33: 0 | R33: 0 | S33: 2
A34: 32 | B34: Arpit Acharya | C34: 88 | D34: 88V1033 | E34: JYOTI SINGH | F34: 31 | G34: - | H34: - | I34: - | J34: - | K34: - | N34: 0 | O34: 0.5 | P34: 0 | Q34: 0 | R34: 0
A35: 33 | B35: Manazir | C35: 88 | D35: 88V1035 | E35: SUGANDHA | F35: 31 | G35: 0 | H35: 1 | I35: 0 | J35: 0 | K35: 0 | M35: Late upto 10:30= 01 | N35: 0.5 | O35: 0.5 | P35: 0 | Q35: 0 | R35: 0
A36: 34 | B36: PORIKHIT DAS | C36: 88 | D36: 88V1047 | E36: PORIKHIT DAS | F36: 31 | G36: 0 | H36: 7 | I36: 2 | J36: 0 | K36: 0 | M36: Late upto 10:30= 13 | N36: 0.5 | O36: 0.5 | P36: 3 | Q36: 1 | R36: 2
A37: 35 | B37: Manazir | C37: 88 | D37: 88V1050 | E37: MANAZIR | F37: 31 | G37: 0 | H37: 1 | I37: 0 | J37: 0 | K37: 0 | M37: Late upto 10:30= 13 | N37: 0 | O37: 0 | P37: 0 | Q37: 1 | R37: 0 | S37: 2
A38: 36 | B38: Manazir | C38: 88 | D38: 88V1051 | E38: SOHRAB HAIDAR | F38: 31 | G38: 0 | H38: 2 | I38: 0 | J38: 0 | K38: 0 | M38: Late upto 10:30= 11 | N38: 0 | O38: 1 | P38: 0 | Q38: 1 | R38: 0
A39: 37 | B39: Hyderabad | C39: 88 | D39: 88V1052 | E39: Anita Dubey | F39: 31 | G39: - | H39: - | I39: - | J39: - | K39: -
A40: 38 | B40: Manmohan | C40: 88 | D40: 88V1057 | E40: Aman Singh | F40: 31 | G40: - | H40: - | I40: - | J40: - | K40: -
...

Sheet Non HDFC 2
A1: Transaction_Reference_No | B1: Beneficiary_Name | C1: Amount | D1: Remitter_Details | E1: Debit_Account_System | F1: Originator_Of_Remittance | G1: Email_ID_Mobile_No
A2: 1 | B2: Narayan Kasat | C2: =VLOOKUP(B2,'Draft-Paysheet May 2026'!$C$4:$AL$51,37,0) -> #REF! | D2: 88ACADEMICS INDIA PRIVATE LIMITED | F2: 88ACADEMICS INDIA PRIVATE LIMITED | G2: 9891054411
A3: 2 | B3: Babu Lal | C3: =VLOOKUP(B3,'Draft-Paysheet May 2026'!$C$4:$AL$51,37,0) -> #REF! | D3: 88ACADEMICS INDIA PRIVATE LIMITED | F3: 88ACADEMICS INDIA PRIVATE LIMITED | G3: 9873030060
A4: 3 | B4: Gulshan | C4: =VLOOKUP(B4,'Draft-Paysheet May 2026'!$C$4:$AL$51,37,0) -> #REF! | D4: 88ACADEMICS INDIA PRIVATE LIMITED | F4: 88ACADEMICS INDIA PRIVATE LIMITED | G4: 9717013679
A5: 4 | B5: Rashi Gupta | C5: =VLOOKUP(B5,'Draft-Paysheet May 2026'!$C$4:$AL$51,37,0) -> #REF! | D5: 88ACADEMICS INDIA PRIVATE LIMITED | F5: 88ACADEMICS INDIA PRIVATE LIMITED | G5: 9654365202
A6: 5 | B6: Raj Kamal Sharma | C6: =VLOOKUP(B6,'Draft-Paysheet May 2026'!$C$4:$AL$51,37,0) -> #REF! | D6: 88ACADEMICS INDIA PRIVATE LIMITED | F6: 88ACADEMICS INDIA PRIVATE LIMITED | G6: 9968722755
A7: 6 | B7: Roshan Sharma | C7: =VLOOKUP(B7,'Draft-Paysheet May 2026'!$C$4:$AL$51,37,0) -> #REF! | D7: 88ACADEMICS INDIA PRIVATE LIMITED | F7: 88ACADEMICS INDIA PRIVATE LIMITED | G7: 9911811713
A8: 7 | B8: Mohan Kumar | C8: =VLOOKUP(B8,'Draft-Paysheet May 2026'!$C$4:$AL$51,37,0) -> #N/A | D8: 88ACADEMICS INDIA PRIVATE LIMITED | F8: 88ACADEMICS INDIA PRIVATE LIMITED | G8: 9540409376
A9: 8 | B9: Meenakshi Gosai | C9: =VLOOKUP(B9,'Draft-Paysheet May 2026'!$C$4:$AL$51,37,0) -> #REF! | D9: 88ACADEMICS INDIA PRIVATE LIMITED | F9: 88ACADEMICS INDIA PRIVATE LIMITED | G9: 7042668809
A10: 9 | B10: Deepa Chandnani | C10: ='Draft-Paysheet May 2026'!AL13 -> 42000 | D10: 88ACADEMICS INDIA PRIVATE LIMITED | F10: 88ACADEMICS INDIA PRIVATE LIMITED | G10: 9873452523
A11: 10 | B11: Nidhi Gupta | C11: =VLOOKUP(B11,'Draft-Paysheet May 2026'!$C$4:$AL$51,37,0) -> #REF! | D11: 88ACADEMICS INDIA PRIVATE LIMITED | F11: 88ACADEMICS INDIA PRIVATE LIMITED | G11: 9958127672
A12: 11 | B12: Shalini Sharma | C12: =VLOOKUP(B12,'Draft-Paysheet May 2026'!$C$4:$AL$51,37,0) -> #REF! | D12: 88ACADEMICS INDIA PRIVATE LIMITED | F12: 88ACADEMICS INDIA PRIVATE LIMITED | G12: 9999868854
A13: 12 | B13: Vikas Panwar | C13: =VLOOKUP(B13,'Draft-Paysheet May 2026'!$C$4:$AL$51,37,0) -> #REF! | D13: 88ACADEMICS INDIA PRIVATE LIMITED | F13: 88ACADEMICS INDIA PRIVATE LIMITED | G13: 8755629335
A14: 13 | B14: Maheen Ajmali | C14: =VLOOKUP(B14,'Draft-Paysheet May 2026'!$C$4:$AL$51,37,0) -> #REF! | D14: 88ACADEMICS INDIA PRIVATE LIMITED | F14: 88ACADEMICS INDIA PRIVATE LIMITED | G14: 9873907268
A15: 14 | B15: Neelansh Pandey | C15: =VLOOKUP(B15,'Draft-Paysheet May 2026'!$C$4:$AL$51,37,0) -> #N/A | D15: 88ACADEMICS INDIA PRIVATE LIMITED | F15: 88ACADEMICS INDIA PRIVATE LIMITED | G15: 9696472351
A16: 15 | B16: Arpit Acharya | C16: =VLOOKUP(B16,'Draft-Paysheet May 2026'!$C$4:$AL$51,37,0) -> #REF! | D16: 88ACADEMICS INDIA PRIVATE LIMITED | F16: 88ACADEMICS INDIA PRIVATE LIMITED | G16: 8273317514
A17: 16 | B17: Sandeep Maurya | C17: =VLOOKUP(B17,'Draft-Paysheet May 2026'!$C$4:$AL$51,37,0) -> #REF! | D17: 88ACADEMICS INDIA PRIVATE LIMITED | F17: 88ACADEMICS INDIA PRIVATE LIMITED | G17: 8268890388
A18: 17 | B18: Priya Madan | C18: =VLOOKUP(B18,'Draft-Paysheet May 2026'!$C$4:$AL$51,37,0) -> #REF! | D18: 88ACADEMICS INDIA PRIVATE LIMITED | F18: 88ACADEMICS INDIA PRIVATE LIMITED | G18: 7379258598
A19: 18 | B19: Monika Dhingra | C19: =VLOOKUP(B19,'Draft-Paysheet May 2026'!$C$4:$AL$51,37,0) -> #REF! | D19: 88ACADEMICS INDIA PRIVATE LIMITED | F19: 88ACADEMICS INDIA PRIVATE LIMITED | G19: 9654797629
A20: 19 | B20: Jyoti Singh | C20: =VLOOKUP(B20,'Draft-Paysheet May 2026'!$C$4:$AL$51,37,0) -> #REF! | D20: 88ACADEMICS INDIA PRIVATE LIMITED | F20: 88ACADEMICS INDIA PRIVATE LIMITED | G20: 9873040788
A21: 20 | B21: Sugandha Bhatnagar | C21: =VLOOKUP(B21,'Draft-Paysheet May 2026'!$C$4:$AL$51,37,0) -> #REF! | D21: 88ACADEMICS INDIA PRIVATE LIMITED | F21: 88ACADEMICS INDIA PRIVATE LIMITED | G21: 7982537821
A22: 21 | B22: Porikhit Das | C22: =VLOOKUP(B22,'Draft-Paysheet May 2026'!$C$4:$AL$51,37,0) -> #REF! | D22: 88ACADEMICS INDIA PRIVATE LIMITED | F22: 88ACADEMICS INDIA PRIVATE LIMITED | G22: 8534999427
... A41: 40 | B41: Sagar Varma | C41: =VLOOKUP(B41,'Draft-Paysheet May 2026'!$C$4:$AL$51,37,0) -> #REF! | D41: 88ACADEMICS INDIA PRIVATE LIMITED | F41: 88ACADEMICS INDIA PRIVATE LIMITED | G41: 7054311774
A42: 41 | B42: Aisha Sidhika | C42: =VLOOKUP(B42,'Draft-Paysheet May 2026'!$C$4:$AL$51,37,0) -> #REF! | D42: 88ACADEMICS INDIA PRIVATE LIMITED | F42: 88ACADEMICS INDIA PRIVATE LIMITED
A43: 42 | B43: Riya | C43: =VLOOKUP(B43,'Draft-Paysheet May 2026'!$C$4:$AL$51,37,0) -> #REF! | D43: 88ACADEMICS INDIA PRIVATE LIMITED | F43: 88ACADEMICS INDIA PRIVATE LIMITED
B45: Total | C45: =SUM(C2:C44) -> #REF!

Sheet New HDFC
A2: SL_NO | B2: Employee Code | C2: Employee Name | D2: Account no | E2: AMOUNT
A4: 1 | B4: 88A1004 | C4: Ajay Kumar Saxena | D4: =VLOOKUP(C4,'Draft-Paysheet May 2026'!$C$4:$Q$51,15,0) -> 50100446028500 | E4: =VLOOKUP(C4,'Draft-Paysheet May 2026'!$C$4:$AL$51,37,0) -> #REF!
A5: 2 | B5: 88G1004 | C5: Simran Kumari Arora | D5: =VLOOKUP(C5,'Draft-Paysheet May 2026'!$C$4:$Q$51,15,0) -> #N/A | E5: =VLOOKUP(C5,'Draft-Paysheet May 2026'!$C$4:$AL$51,37,0) -> #N/A
A6: 3 | B6: 88G1013 | C6: Jyoti Pal | D6: =VLOOKUP(C6,'Draft-Paysheet May 2026'!$C$4:$Q$51,15,0) -> 50100151532802 | E6: =VLOOKUP(C6,'Draft-Paysheet May 2026'!$C$4:$AL$51,37,0) -> #REF!
A7: 4 | B7: 88G1032 | C7: Kiran Pathak | D7: =VLOOKUP(C7,'Draft-Paysheet May 2026'!$C$4:$Q$51,15,0) -> #N/A | E7: =VLOOKUP(C7,'Draft-Paysheet May 2026'!$C$4:$AL$51,37,0) -> #N/A
A8: 5 | B8: 88G1074 | C8: Rakesh Singh Rawat | D8: =VLOOKUP(C8,'Draft-Paysheet May 2026'!$C$4:$Q$51,15,0) -> #N/A | E8: =VLOOKUP(C8,'Draft-Paysheet May 2026'!$C$4:$AL$51,37,0) -> #N/A
A9: 6 | B9: 88G1078 | C9: Pinku Kumar | D9: =VLOOKUP(C9,'Draft-Paysheet May 2026'!$C$4:$Q$51,15,0) -> 50100754820324 | E9: =VLOOKUP(C9,'Draft-Paysheet May 2026'!$C$4:$AL$51,37,0) -> #REF!
A10: 7 | B10: 88V1003 | C10: Rachna Ajmani | D10: =VLOOKUP(C10,'Draft-Paysheet May 2026'!$C$4:$Q$51,15,0) -> 50100067622091 | E10: =VLOOKUP(C10,'Draft-Paysheet May 2026'!$C$4:$AL$51,37,0) -> #REF!
A11: 8 | B11: 88V1006 | C11: Shalu Gandhi | D11: =VLOOKUP(C11,'Draft-Paysheet May 2026'!$C$4:$Q$51,15,0) -> #N/A | E11: =VLOOKUP(C11,'Draft-Paysheet May 2026'!$C$4:$AL$51,37,0) -> #N/A
A12: 9 | B12: 88V1007 | C12: Bhola Sharma | D12: =VLOOKUP(C12,'Draft-Paysheet May 2026'!$C$4:$Q$51,15,0) -> #N/A | E12: =VLOOKUP(C12,'Draft-Paysheet May 2026'!$C$4:$AL$51,37,0) -> #N/A
A13: 10 | B13: 88V1008 | C13: Sumant sharma | D13: =VLOOKUP(C13,'Draft-Paysheet May 2026'!$C$4:$Q$51,15,0) -> #N/A | E13: =VLOOKUP(C13,'Draft-Paysheet May 2026'!$C$4:$AL$51,37,0) -> #N/A
A14: 11 | B14: 88V1019 | C14: Deepinder Kumar Anand | D14: =VLOOKUP(C14,'Draft-Paysheet May 2026'!$C$4:$Q$51,15,0) -> #N/A | E14: =VLOOKUP(C14,'Draft-Paysheet May 2026'!$C$4:$AL$51,37,0) -> #N/A
A15: 12 | B15: 88V1029 | C15: Sandeep | D15: =VLOOKUP(C15,'Draft-Paysheet May 2026'!$C$4:$Q$51,15,0) -> 50100255004836 | E15: =VLOOKUP(C15,'Draft-Paysheet May 2026'!$C$4:$AL$51,37,0) -> #REF!
... A27: 24 | B27: 88V1114 | C27: Khushi Rupesh Subramanian | D27: =VLOOKUP(C27,'Draft-Paysheet May 2026'!$C$4:$Q$51,15,0) -> #N/A | E27: =VLOOKUP(C27,'Draft-Paysheet May 2026'!$C$4:$AL$51,37,0) -> #N/A
A28: 25 | B28: 88V1115 | C28: Unnati Singh | D28: =VLOOKUP(C28,'Draft-Paysheet May 2026'!$C$4:$Q$51,15,0) -> 50100810089015 | E28: =VLOOKUP(C28,'Draft-Paysheet May 2026'!$C$4:$AL$51,37,0) -> #REF! | K28: =20000 -> 20000
A29: 26 | B29: 88V1117 | C29: Krishan Pal Singh | D29: =VLOOKUP(C29,'Draft-Paysheet May 2026'!$C$4:$Q$51,15,0) -> #N/A | E29: =VLOOKUP(C29,'Draft-Paysheet May 2026'!$C$4:$AL$51,37,0) -> #N/A | K29: =K28/30*4 -> 2666.6667
A30: 27 | B30: 88V1120 | C30: Aayushi Pinakin Dhuvad | D30: =VLOOKUP(C30,'Draft-Paysheet May 2026'!$C$4:$Q$51,15,0) -> #N/A | E30: =VLOOKUP(C30,'Draft-Paysheet May 2026'!$C$4:$AL$51,37,0) -> #N/A | K30: =SUM(K28:K29) -> 22666.667
A31: 28 | C31: Sunil | E31: 22667
C33: Total | E33: =SUM(E4:E32) -> #REF!

Sheet Non HDFC for Bank
A1: Remitter_Account No. | B1: Remitter_Details | C1: Beneficiary_Name | D1: Amount | E1: IFSC Code | F1: Bank_Account_Number | G1: Beneficiary LEI Code
A2: 50200059258233 | B2: 88ACADEMICS INDIA PRIVATE LIMITED | C2: Narayan Kasat | D2: =VLOOKUP(C2,'Draft-Paysheet May 2026'!$C$4:$AL$51,37,0) -> #REF! | E2: =VLOOKUP(C2,'Draft-Paysheet May 2026'!$C$4:$R$51,16,0) -> UTIB0004626 | F2: =VLOOKUP(C2,'Draft-Paysheet May 2026'!$C$4:$R$51,15,0) -> 921010013386877
A3: 50200059258233 | B3: 88ACADEMICS INDIA PRIVATE LIMITED | C3: Babu Lal | D3: =VLOOKUP(C3,'Draft-Paysheet May 2026'!$C$4:$AL$51,37,0) -> #REF! | E3: =VLOOKUP(C3,'Draft-Paysheet May 2026'!$C$4:$R$51,16,0) -> UTIB0001007 | F3: =VLOOKUP(C3,'Draft-Paysheet May 2026'!$C$4:$R$51,15,0) -> 911010047193187
A4: 50200059258233 | B4: 88ACADEMICS INDIA PRIVATE LIMITED | C4: Gulshan | D4: =VLOOKUP(C4,'Draft-Paysheet May 2026'!$C$4:$AL$51,37,0) -> #REF! | E4: =VLOOKUP(C4,'Draft-Paysheet May 2026'!$C$4:$R$51,16,0) -> KVBL0004101 | F4: =VLOOKUP(C4,'Draft-Paysheet May 2026'!$C$4:$R$51,15,0) -> 4101155000110629
A5: 50200059258233 | B5: 88ACADEMICS INDIA PRIVATE LIMITED | C5: Rashi Gupta | D5: =VLOOKUP(C5,'Draft-Paysheet May 2026'!$C$4:$AL$51,37,0) -> #REF! | E5: =VLOOKUP(C5,'Draft-Paysheet May 2026'!$C$4:$R$51,16,0) -> SBIN0050324 | F5: =VLOOKUP(C5,'Draft-Paysheet May 2026'!$C$4:$R$51,15,0) -> 65122570810
A6: 50200059258233 | B6: 88ACADEMICS INDIA PRIVATE LIMITED | C6: Raj Kamal Sharma | D6: =VLOOKUP(C6,'Draft-Paysheet May 2026'!$C$4:$AL$51,37,0) -> #REF! | E6: =VLOOKUP(C6,'Draft-Paysheet May 2026'!$C$4:$R$51,16,0) -> SBIN0018166 | F6: =VLOOKUP(C6,'Draft-Paysheet May 2026'!$C$4:$R$51,15,0) -> 31582334723
A7: 50200059258233 | B7: 88ACADEMICS INDIA PRIVATE LIMITED | C7: Roshan Sharma | D7: =VLOOKUP(C7,'Draft-Paysheet May 2026'!$C$4:$AL$51,37,0) -> #REF! | E7: =VLOOKUP(C7,'Draft-Paysheet May 2026'!$C$4:$R$51,16,0) -> MAHB0001744 | F7: =VLOOKUP(C7,'Draft-Paysheet May 2026'!$C$4:$R$51,15,0) -> 60285501118
A8: 50200059258233 | B8: 88ACADEMICS INDIA PRIVATE LIMITED | C8: Mohan Kumar | D8: =VLOOKUP(C8,'Draft-Paysheet May 2026'!$C$4:$AL$51,37,0) -> #N/A | E8: =VLOOKUP(C8,'Draft-Paysheet May 2026'!$C$4:$R$51,16,0) -> #N/A | F8: =VLOOKUP(C8,'Draft-Paysheet May 2026'!$C$4:$R$51,15,0) -> #N/A
A9: 50200059258233 | B9: 88ACADEMICS INDIA PRIVATE LIMITED | C9: Meenakshi Gosai | D9: =VLOOKUP(C9,'Draft-Paysheet May 2026'!$C$4:$AL$51,37,0) -> #REF! | E9: =VLOOKUP(C9,'Draft-Paysheet May 2026'!$C$4:$R$51,16,0) -> IOBA0000766 | F9: =VLOOKUP(C9,'Draft-Paysheet May 2026'!$C$4:$R$51,15,0) -> 076601000061190
A10: 50200059258233 | B10: 88ACADEMICS INDIA PRIVATE LIMITED | C10: Deepa Chandnani | D10: ='Draft-Paysheet May 2026'!AL13 -> 42000 | E10: ='Draft-Paysheet May 2026'!R13 -> SBIN0032160 | F10: ='Draft-Paysheet May 2026'!Q13 -> 51116630705
A11: 50200059258233 | B11: 88ACADEMICS INDIA PRIVATE LIMITED | C11: Nidhi Gupta | D11: =VLOOKUP(C11,'Draft-Paysheet May 2026'!$C$4:$AL$51,37,0) -> #REF! | E11: =VLOOKUP(C11,'Draft-Paysheet May 2026'!$C$4:$R$51,16,0) -> CNRB0003160 | F11: =VLOOKUP(C11,'Draft-Paysheet May 2026'!$C$4:$R$51,15,0) -> 110037818923
A12: 50200059258233 | B12: 88ACADEMICS INDIA PRIVATE LIMITED | C12: Shalini Sharma | D12: =VLOOKUP(C12,'Draft-Paysheet May 2026'!$C$4:$AL$51,37,0) -> #REF! | E12: =VLOOKUP(C12,'Draft-Paysheet May 2026'!$C$4:$R$51,16,0) -> SBIN0011550 | F12: =VLOOKUP(C12,'Draft-Paysheet May 2026'!$C$4:$R$51,15,0) -> 20088263301
A13: 50200059258233 | B13: 88ACADEMICS INDIA PRIVATE LIMITED | C13: Vikas Panwar | D13: =VLOOKUP(C13,'Draft-Paysheet May 2026'!$C$4:$AL$51,37,0) -> #REF! | E13: =VLOOKUP(C13,'Draft-Paysheet May 2026'!$C$4:$R$51,16,0) -> KKBK0004596 | F13: =VLOOKUP(C13,'Draft-Paysheet May 2026'!$C$4:$R$51,15,0) -> 5246430031
A14: 50200059258233 | B14: 88ACADEMICS INDIA PRIVATE LIMITED | C14: Maheen Ajmali | D14: =VLOOKUP(C14,'Draft-Paysheet May 2026'!$C$4:$AL$51,37,0) -> #REF! | E14: =VLOOKUP(C14,'Draft-Paysheet May 2026'!$C$4:$R$51,16,0) -> SBIN0005918 | F14: =VLOOKUP(C14,'Draft-Paysheet May 2026'!$C$4:$R$51,15,0) -> 35853508559
A15: 50200059258233 | B15: 88ACADEMICS INDIA PRIVATE LIMITED | C15: Neelansh Pandey | D15: =VLOOKUP(C15,'Draft-Paysheet May 2026'!$C$4:$AL$51,37,0) -> #N/A | E15: =VLOOKUP(C15,'Draft-Paysheet May 2026'!$C$4:$R$51,16,0) -> #N/A | F15: =VLOOKUP(C15,'Draft-Paysheet May 2026'!$C$4:$R$51,15,0) -> #N/A
A16: 50200059258233 | B16: 88ACADEMICS INDIA PRIVATE LIMITED | C16: Arpit Acharya | D16: =VLOOKUP(C16,'Draft-Paysheet May 2026'!$C$4:$AL$51,37,0) -> #REF! | E16: =VLOOKUP(C16,'Draft-Paysheet May 2026'!$C$4:$R$51,16,0) -> HDFC0007285 | F16: =VLOOKUP(C16,'Draft-Paysheet May 2026'!$C$4:$R$51,15,0) -> 50100823730034
A17: 50200059258233 | B17: 88ACADEMICS INDIA PRIVATE LIMITED | C17: Sandeep Maurya | D17: =VLOOKUP(C17,'Draft-Paysheet May 2026'!$C$4:$AL$51,37,0) -> #REF! | E17: =VLOOKUP(C17,'Draft-Paysheet May 2026'!$C$4:$R$51,16,0) -> ICIC0000815 | F17: =VLOOKUP(C17,'Draft-Paysheet May 2026'!$C$4:$R$51,15,0) -> 051601003530
A18: 50200059258233 | B18: 88ACADEMICS INDIA PRIVATE LIMITED | C18: Priya Madan | D18: =VLOOKUP(C18,'Draft-Paysheet May 2026'!$C$4:$AL$51,37,0) -> #REF! | E18: =VLOOKUP(C18,'Draft-Paysheet May 2026'!$C$4:$R$51,16,0) -> UTIB0000739 | F18: =VLOOKUP(C18,'Draft-Paysheet May 2026'!$C$4:$R$51,15,0) -> 911010066143864
A19: 50200059258233 | B19: 88ACADEMICS INDIA PRIVATE LIMITED | C19: Monika Dhingra | D19: =VLOOKUP(C19,'Draft-Paysheet May 2026'!$C$4:$AL$51,37,0) -> #REF! | E19: =VLOOKUP(C19,'Draft-Paysheet May 2026'!$C$4:$R$51,16,0) -> ICIC0006301 | F19: =VLOOKUP(C19,'Draft-Paysheet May 2026'!$C$4:$R$51,15,0) -> 630101511988
A20: 50200059258233 | B20: 88ACADEMICS INDIA PRIVATE LIMITED | C20: Jyoti Singh | D20: =VLOOKUP(C20,'Draft-Paysheet May 2026'!$C$4:$AL$51,37,0) -> #REF! | E20: =VLOOKUP(C20,'Draft-Paysheet May 2026'!$C$4:$R$51,16,0) -> ICIC0007218 | F20: =VLOOKUP(C20,'Draft-Paysheet May 2026'!$C$4:$R$51,15,0) -> 721801500772
A21: 50200059258233 | B21: 88ACADEMICS INDIA PRIVATE LIMITED | C21: Sugandha Bhatnagar | D21: =VLOOKUP(C21,'Draft-Paysheet May 2026'!$C$4:$AL$51,37,0) -> #REF! | E21: =VLOOKUP(C21,'Draft-Paysheet May 2026'!$C$4:$R$51,16,0) -> IDIB000T553 | F21: =VLOOKUP(C21,'Draft-Paysheet May 2026'!$C$4:$R$51,15,0) -> 59084158508
A22: 50200059258233 | B22: 88ACADEMICS INDIA PRIVATE LIMITED | C22: Porikhit Das | D22: =VLOOKUP(C22,'Draft-Paysheet May 2026'!$C$4:$AL$51,37,0) -> #REF! | E22: =VLOOKUP(C22,'Draft-Paysheet May 2026'!$C$4:$R$51,16,0) -> KKBK0004575 | F22: =VLOOKUP(C22,'Draft-Paysheet May 2026'!$C$4:$R$51,15,0) -> 7546347903
... A42: 50200059258233 | B42: 88ACADEMICS INDIA PRIVATE LIMITED | C42: Aisha Sidhika | D42: =VLOOKUP(C42,'Draft-Paysheet May 2026'!$C$4:$AL$51,37,0) -> #REF! | E42: =VLOOKUP(C42,'Draft-Paysheet May 2026'!$C$4:$R$51,16,0) -> PUNB0491900 | F42: =VLOOKUP(C42,'Draft-Paysheet May 2026'!$C$4:$R$51,15,0) -> 4919000100044435
A43: 50200059258233 | B43: 88ACADEMICS INDIA PRIVATE LIMITED | C43: Riya | D43: =VLOOKUP(C43,'Draft-Paysheet May 2026'!$C$4:$AL$51,37,0) -> #REF! | E43: =VLOOKUP(C43,'Draft-Paysheet May 2026'!$C$4:$R$51,16,0) -> CNRB0019904 | F43: ='Draft-Paysheet May 2026'!Q51 -> 110043317026
C45: Total | D45: =SUM(D2:D44) -> #REF!

Sheet Leavers
A1: PAY_DATE | B1: Employee Code | C1: Employee Name | D1: Date of Join | E1: Gender | F1: Date of Birth | G1: Date of Leaving | H1: Father Name | I1: Department | J1: Designation | K1: Cost_Centre | L1: Work Location | M1: UAN_No | N1: PAN | O1: Aadhaar Number | P1: Bank Name | Q1: Account_No | R1: IFSC_Code | S1: Name As Per Bank | T1: Nationality | U1: Mobile Number | V1: Email ID | W1: STDDAYS | X1: LOP DAYS | Y1: WRKDAYS | Z1: Basic | AA1: Basic Arrear | AB1: House Rent Allowance | AC1: HRA Arrear | AD1: Special Allowance | AE1: LOP Reversals | AF1: Other Benefit | AG1: Total Salary | AH1: Salary Payable | AI1: TDS | AJ1: Monthly TDS | AK1: Provident Fund | AL1: PF Arrears | AM1: LWF | AN1: Net Salary Payable
A2: 30/11/2025 | B2: 88G1004 | C2: Simran Kumari Arora | D2: 01/11/2021 | E2: F | F2: 19/12/1996 | G2: 45930 | H2: Ramesh Arora | I2: Academic | J2: Asst. Manager | K2: NEW DELHI | L2: NEW DELHI | N2: DCXPA5508M | O2: 400878015992 | P2: HDFC BANK LTD | Q2: 50100367679688 | R2: HDFC0004754 | S2: Simran Arora | T2: INDIAN | U2: 7838783381 | V2: simranarora121996@gmail.com | W2: 31 | X2: 31 | Y2: =W2-X2 -> 0 | Z2: 23650 | AA2: 0 | AB2: 0 | AC2: 0 | AD2: 0 | AG2: =SUM(Z2:AD2) -> 23650 | AH2: =ROUND(AG2/W2*Y2,0) -> 0 | AK2: 0 | AL2: 0 | AM2: 0 | AN2: =AH2-SUM(AJ2:AM2) -> 0 | AQ2: 23650
A3: 30/11/2025 | B3: 88G1032 | C3: Kiran Pathak | D3: 06/04/2022 | E3: F | F3: 09/07/1996 | G3: 45930 | H3: Mr. Shiv Charan Pathak | I3: Academic | J3: Asst. Manager | K3: NEW DELHI | L3: NEW DELHI | N3: DHPPP5580M | O3: 441344227722 | P3: HDFC BANK LTD | Q3: 50100570445568 | R3: HDFC0004754 | S3: Kiran Pathak | T3: INDIAN | U3: 9911369360 | V3: pathakkiran233@gmail.com | W3: 31 | X3: 31 | Y3: =W3-X3 -> 0 | Z3: 23650 | AA3: 0 | AB3: 0 | AC3: 0 | AD3: 0 | AG3: =SUM(Z3:AD3) -> 23650 | AH3: =ROUND(AG3/W3*Y3,0) -> 0 | AK3: 0 | AL3: 0 | AM3: 0 | AN3: =AH3-SUM(AJ3:AM3) -> 0 | AQ3: 23650
A4: 30/11/2025 | B4: 88G1076 | C4: Neelansh Pandey | D4: 27/03/2023 | E4: M | F4: 29/12/1999 | G4: 45930 | H4: Maneesh Pandey | I4: Technology | J4: Software Engineer | K4: NEW DELHI | L4: NEW DELHI | N4: GBWPP6646A | O4: 725384430510 | P4: FEDERAL BANK | Q4: 55550125053999 | R4: FDRL0005555 | S4: Neelansh Pandey | T4: INDIAN | U4: 9696472351 | V4: neelansh.email@gmail.com | W4: 31 | X4: 31 | Y4: =W4-X4 -> 0 | Z4: 21000 | AA4: 0 | AB4: 6500 | AC4: 0 | AD4: 0 | AG4: =SUM(Z4:AD4) -> 27500 | AH4: =ROUND(AG4/W4*Y4,0) -> 0 | AK4: 0 | AL4: 0 | AM4: 0 | AN4: =AH4-SUM(AJ4:AM4) -> 0
A5: 30/11/2025 | B5: 88V1006 | C5: Shalu Gandhi | D5: 01/11/2021 | E5: F | F5: 02/04/1994 | G5: 45946 | H5: Mr. Manoj Kumar | I5: VGLD | J5: Business Development Manager | K5: NEW DELHI | L5: NEW DELHI | N5: FTEPS2950H | O5: 521413766561 | P5: HDFC BANK LTD | Q5: 50100320374664 | R5: HDFC0004400 | S5: Shalu Gandhi | T5: INDIAN | U5: 8178558699 | V5: Princessshalu41@gmail.com | W5: 31 | X5: =(16-0.4) -> 15.6 | Y5: =W5-X5 -> 15.4 | Z5: 21000 | AA5: 0 | AB5: 9500 | AC5: 0 | AD5: 9500 | AG5: =SUM(Z5:AD5) -> 40000 | AH5: =ROUND(AG5/W5*Y5,0) -> 19871 | AK5: 0 | AL5: 0 | AM5: 0 | AN5: =AH5-SUM(AJ5:AM5) -> 19871
A6: 30/11/2025 | B6: 88V1007 | C6: Bhola Sharma | D6: 01/11/2021 | E6: M | F6: 21/03/1990 | G6: 45930 | H6: Ram Briksh Sharma | I6: IT | J6: Team Lead | K6: NEW DELHI | L6: NEW DELHI | N6: EMTPS5809G | O6: 358945706233 | P6: HDFC BANK LTD | Q6: 50100671464827 | R6: HDFC0002509 | S6: Bhola Sharma | T6: INDIAN | U6: 8010418160 | V6: bhola334@gmail.com | W6: 31 | X6: 31 | Y6: =W6-X6 -> 0 | Z6: 32100 | AA6: 0 | AB6: 16050 | AC6: 0 | AD6: 16050 | AG6: =SUM(Z6:AD6) -> 64200 | AH6: =ROUND(AG6/W6*Y6,0) -> 0 | AK6: 0 | AL6: 0 | AM6: 0 | AN6: =AH6-SUM(AJ6:AM6) -> 0
A7: 30/11/2025 | B7: 88V1008 | C7: Sumant sharma | D7: 01/11/2021 | E7: M | F7: 26/06/1997 | G7: 45930 | H7: Mr. Dayanand Sharma | I7: IT | J7: Jr. Software Engineer | K7: NEW DELHI | L7: NEW DELHI | N7: MBWPS9718L | O7: 436349720443 | P7: HDFC BANK LTD | Q7: 50100471094691 | R7: HDFC0002509 | S7: Sumant sharma | T7: INDIAN | U7: 8115019830 | V7: sharmasumant092@gmail.com | W7: 31 | X7: 31 | Y7: =W7-X7 -> 0 | Z7: 25000 | AA7: 0 | AB7: 0 | AC7: 0 | AD7: 0 | AG7: =SUM(Z7:AD7) -> 25000 | AH7: =ROUND(AG7/W7*Y7,0) -> 0 | AK7: 0 | AL7: 0 | AM7: 0 | AN7: =AH7-SUM(AJ7:AM7) -> 0
A8: 30/11/2025 | B8: 88V1019 | C8: Deepinder Kumar Anand | D8: 01/08/2022 | E8: M | F8: 19/08/1989 | G8: 45930 | H8: Gyan Chand | I8: VGLD | J8: Manager | K8: NEW DELHI | L8: NEW DELHI | N8: BJSPA7312P | O8: 866993461179 | P8: HDFC BANK LTD | Q8: 50100374469868 | R8: HDFC0004754 | S8: Deepinder Kumar Anand | T8: INDIAN | U8: 8527697920 | V8: deependeranand89@gmail.com | W8: 31 | X8: 31 | Y8: =W8-X8 -> 0 | Z8: 30250 | AA8: 0 | AB8: 15125 | AC8: 0 | AD8: 15125 | AG8: =SUM(Z8:AD8) -> 60500 | AH8: =ROUND(AG8/W8*Y8,0) -> 0 | AK8: 0 | AL8: 0 | AM8: 0 | AN8: =AH8-SUM(AJ8:AM8) -> 0
A9: 30/11/2025 | B9: 88V1074 | C9: Shailja Dhyani | D9: 18/03/2024 | E9: F | F9: 15/09/1980 | G9: 45930 | H9: Gangaram Bhardwaj | I9: Technology | J9: Software Engineer | K9: NEW DELHI | L9: NEW DELHI | N9: ASLPD0880A | O9: 952955251762 | P9: STATE BANK OF INDIA | Q9: 30838184866 | R9: SBIN0032182 | S9: Shailja Dhyani | T9: Indian | U9: 9205031014 | V9: dhyani.shailja@gmail.com | W9: 31 | X9: 31 | Y9: =W9-X9 -> 0 | Z9: 21000 | AA9: 0 | AB9: 7000 | AC9: 0 | AD9: 0 | AG9: =SUM(Z9:AD9) -> 28000 | AH9: =ROUND(AG9/W9*Y9,0) -> 0 | AK9: 0 | AL9: 0 | AM9: 0 | AN9: =AH9-SUM(AJ9:AM9) -> 0
A10: 30/11/2025 | B10: 88V1082 | C10: Neha Dhall | D10: 24/04/2024 | E10: F | F10: 12/07/2000 | G10: 45958 | H10: Parveen Dhall | I10: VGLD | J10: Business Development Manager | K10: NEW DELHI | L10: NEW DELHI | N10: EZLPD7666B | O10: 607133965459 | P10: UNION BANK OF INDIA | Q10: 639502010012535 | R10: UBIN0563951 | S10: Neha Dhall | T10: Indian | U10: 9711826778 | V10: dhallneha2000@gmail.com | W10: 31 | X10: 5.5 | Y10: =W10-X10 -> 25.5 | Z10: 21000 | AA10: 0 | AB10: 4300 | AC10: 0 | AD10: 0 | AG10: =SUM(Z10:AD10) -> 25300 | AH10: =ROUND(AG10/W10*Y10,0) -> 20811 | AK10: 0 | AL10: 0 | AM10: 0 | AN10: =AH10-SUM(AJ10:AM10) -> 20811
A11: 30/11/2025 | B11: 88V1084 | C11: Ankita Rajput | D11: 08/05/2024 | E11: F | F11: 02/05/2001 | G11: 45930 | H11: suresh chandra | I11: VGLD | J11: Business Development Manager | K11: NEW DELHI | L11: NEW DELHI | N11: EFGPR7171A | O11: 417687447753 | P11: STATE BANK OF INDIA | Q11: 38532821158 | R11: SBIN0061203 | S11: Ankita Rajput | T11: Indian | U11: 9315039537 | V11: iamankitarajput3@gmail.com | W11: 31 | X11: 31 | Y11: =W11-X11 -> 0 | Z11: 25000 | AA11: 0 | AB11: 0 | AC11: 0 | AD11: 0 | AG11: =SUM(Z11:AD11) -> 25000 | AH11: =ROUND(AG11/W11*Y11,0) -> 0 | AK11: 0 | AL11: 0 | AM11: 0 | AN11: =AH11-SUM(AJ11:AM11) -> 0 | AR11: 25000
A12: 31-12-2025 | B12: 88G1074 | C12: Rakesh Singh Rawat | D12: 14/03/2023 | E12: M | F12: 03/05/1976 | G12: 45972 | H12: Balwant Singh Rawat | I12: Academic | J12: Asst. Manager | K12: NEW DELHI | L12: NEW DELHI | N12: BUYPR5567C | O12: 621229408319 | P12: HDFC BANK LTD | Q12: 50100605279393 | R12: HDFC0003687 | S12: Rakesh Singh Rawat | T12: INDIAN | U12: 9013600858 | V12: rsrawatdtp9@gmail.com | W12: 31 | X12: 0 | Y12: =W12-X12 -> 31 | Z12: 21000 | AA12: 0 | AB12: 3200 | AC12: 0 | AD12: 0 | AE12: =SUM(Z12:AD12) -> 24200 | AF12: =ROUND(AE12/W12*Y12,0) -> 24200 | AJ12: 0 | AK12: 0 | AL12: 0 | AM12: =AF12-SUM(AI12:AL12) -> 24200
A13: 31-12-2025 | B13: 88V1054 | C13: Dharna Jain | D13: 04/12/2023 | E13: F | F13: 07/01/2000 | G13: 45880 | H13: Rajesh Jain | I13: VGLD | J13: Business Development Manager | K13: NEW DELHI | L13: NEW DELHI | N13: BVXPJ3487P | O13: 607361874982 | P13: HDFC BANK LTD | Q13: 50100618103035 | R13: HDFC0002091 | S13: Dharna Jain | T13: INDIAN | U13: 954018168 | V13: dharnajain07@gmail.com | W13: 31 | X13: 0 | Y13: =W13-X13 -> 31 | Z13: 21175 | AA13: 0 | AB13: 10588 | AC13: 0 | AD13: 10588 | AE13: =SUM(Z13:AD13) -> 42351 | AF13: =ROUND(AE13/W13*Y13,0) -> 42351 | AJ13: 0 | AK13: 0 | AL13: 0 | AM13: =AF13-SUM(AI13:AL13) -> 42351
A14: 31-12-2025 | B14: 88V1094 | C14: CH Shiva | D14: 08/07/2024 | E14: M | F14: 22/02/1995 | G14: 45850 | H14: Ch Viswanath | I14: VGLD | J14: Business Development Manager | K14: NEW DELHI | L14: NEW DELHI | N14: LZXPS7724L | O14: 708102547472 | P14: BANK OF BARODA | Q14: 05120100031898 | R14: BARB0SECUND | S14: CH Shiva | T14: Indian | U14: 9348489443 | V14: chshiva3877@gmail.com | W14: 31 | X14: 25 | Y14: =W14-X14 -> 6 | Z14: 21000 | AA14: 0 | AB14: 9500 | AC14: 0 | AD14: 9500 | AE14: =SUM(Z14:AD14) -> 40000 | AF14: =ROUND(AE14/W14*Y14,0) -> 7742 | AG14: 1500 | AJ14: 0 | AK14: 0 | AL14: 0 | AM14: =AF14-SUM(AI14:AL14)+AG14 -> 9242
A15: 31-12-2025 | B15: 88V1117 | C15: Krishan Pal Singh | D15: 01/07/2025 | E15: M | F15: 30/06/2000 | G15: 15-12-2025 | H15: Dileep Singh | I15: Academic | J15: Business Development Manager | K15: NEW DELHI | L15: NEW DELHI | N15: LNMPS6237H | O15: 988998640555 | P15: HDFC BANK LTD | Q15: 50100539685358 | R15: HDFC0002670 | S15: Krishan Pal Singh | T15: Indian | U15: 9602349484 | V15: kpbanna.singh05@gmail.com | W15: 31 | X15: 17 | Y15: =W15-X15 -> 14 | Z15: 21000 | AA15: 0 | AB15: 9000 | AC15: 0 | AD15: 9000 | AE15: =SUM(Z15:AD15) -> 39000 | AF15: =ROUND(AE15/W15*Y15,0) -> 17613 | AJ15: 0 | AK15: 0 | AL15: 0 | AM15: =AF15-SUM(AI15:AL15) -> 17613
